<?xml version="1.0"?>
<robot name="my_robot">

  <!-- MATERIALS -->
  <material name="blue">
    <color rgba="0 0 1 1"/>
  </material>

  <material name="purple">
    <color rgba="0.5 0 0.5 1"/>
  </material>

  <material name="red">
    <color rgba="1 0 0 1"/>
  </material>
  
  <!-- BASE LINK (CHASSIS) -->
  <link name="base_link">
    <visual>
      <geometry>
        <box size="0.6 0.4 0.2"/>
      </geometry>
      <material name="blue"/>
    </visual>

    <collision>
      <geometry>
        <box size="0.6 0.4 0.2"/>
      </geometry>
    </collision>

    <inertial>
      <mass value="10.0"/>
      <origin xyz="0 0 0"/>
      <inertia ixx="0.2" iyy="0.2" izz="0.2"
               ixy="0.0" ixz="0.0" iyz="0.0"/>
    </inertial>
  </link>
  <!-- RIGHT WHEEL -->
  <link name="right_wheel">
    <visual>
      <geometry>
        <cylinder length="0.05" radius="0.1"/>
      </geometry>
      <origin rpy="0 1.5707 0" xyz="0 0 0"/>
      <material name="purple"/>
    </visual>

    <collision>
      <geometry>
        <cylinder length="0.05" radius="0.1"/>
      </geometry>
      <origin rpy="0 1.5707 0"/>
    </collision>

    <inertial>
      <mass value="1.0"/>
      <inertia ixx="0.01" iyy="0.01" izz="0.02"
               ixy="0" ixz="0" iyz="0"/>
    </inertial>
  </link>





  <!-- LEFT WHEEL -->
  <link name="left_wheel">
    <visual>
      <geometry>
        <cylinder length="0.05" radius="0.1"/>
      </geometry>
      <origin rpy="0 1.5707 0" xyz="0 0 0"/>
      <material name="purple"/>
    </visual>

    <collision>
      <geometry>
        <cylinder length="0.05" radius="0.1"/>
      </geometry>
      <origin rpy="0 1.5707 0"/>
    </collision>

    <inertial>
      <mass value="1.0"/>
      <inertia ixx="0.01" iyy="0.01" izz="0.02"
               ixy="0" ixz="0" iyz="0"/>
    </inertial>


  </link>


<!-- //front caster wheel -->

    <link name="caster_wheel">
    <visual>
      <geometry>
        <sphere radius="0.05"/>
      </geometry>
      <origin rpy="0 0 0" xyz="0.25 0 -0.025"/>
      <material name="purple"/>
    </visual>

    <collision>
      <geometry>
        <sphere radius="0.05"/>
      </geometry>
      <origin rpy="0 0 0" xyz="0.25 0 -0.025"/>
    </collision>



    <inertial>
      <mass value="0.2"/>
      <inertia ixx="0.0001" iyy="0.0001" izz="0.0001"
               ixy="0" ixz="0" iyz="0"/>
    </inertial>
  </link>



  <!-- // caster wheel at the back -->
    <link name="caster_wheel_back">
    <visual>
      <geometry>
        <sphere radius="0.05"/>
      </geometry>
      <origin rpy="0 0 0" xyz="-0.25 0 -0.025"/>
      <material name="purple"/>
    </visual>

       <collision>
      <geometry>
        <sphere radius="0.05"/>
      </geometry>
      <origin rpy="0 0 0" xyz="-0.25 0 -0.025"/>
    </collision>

    <inertial>
      <mass value="0.2"/>
      <inertia ixx="0.0001" iyy="0.0001" izz="0.0001"
               ixy="0" ixz="0" iyz="0"/>
    </inertial>
  </link>


<!-- //Caster wheel at the back finished  -->





  <!-- LIDAR LINK -->
  <link name="lidar">
    <visual>
      <geometry>
        <cylinder length="0.05" radius="0.1"/>
      </geometry>
      <origin rpy="0 0 0" xyz="0 0 0"/>
      <material name="red"/>
    </visual>

    <collision>
      <geometry>
        <cylinder length="0.05" radius="0.1"/>
      </geometry>
      <origin rpy="0 0 0" xyz="0 0 0"/>
    </collision>

    <inertial>
      <mass value="0.5"/>
      <origin xyz="0 0 0" rpy="0 0 0"/>
      <inertia ixx="0.005" iyy="0.005" izz="0.005"
               ixy="0" ixz="0" iyz="0"/>
    </inertial>
  </link>

  <!-- IMU LINK -->
  <link name="imu_link">
    <inertial>
      <mass value="0.1"/>
      <inertia ixx="0.0001" iyy="0.0001" izz="0.0001"
               ixy="0" ixz="0" iyz="0"/>
    </inertial>
  </link>

  <!-- WHEELS JOINTS -->
  <joint name="base_to_right_wheel" type="continuous">
    <parent link="base_link"/>
    <child link="right_wheel"/>
    <origin xyz="0 -0.230 -0.1" rpy="0 0 1.57"/>
    <axis xyz="1 0 0"/>
  </joint>

  <joint name="base_to_left_wheel" type="continuous">
    <parent link="base_link"/>
    <child link="left_wheel"/>
    <origin xyz="0 0.230 -0.1" rpy="0 0 1.57"/>
    <axis xyz="1 0 0"/>
  </joint>

  <!-- // joint 3 between base link and front caster wheel -->

    <joint name="caster_wheel" type="fixed">
        <parent link="base_link"/>
        <child link="caster_wheel"/>
        <origin rpy="0 0 0" xyz="0 0 -0.125"/>
  </joint>

<!-- // joint 4 between base link and back caster wheel -->

    <joint name="caster_wheel_back" type="fixed">
        <parent link="base_link"/>
        <child link="caster_wheel_back"/>
        <origin rpy="0 0 0" xyz="0 0 -0.125"/>
  </joint>

  <!-- SENSOR JOINTS -->
  <joint name="base_to_lidar" type="fixed">
    <parent link="base_link"/>
    <child link="lidar"/>
    <origin xyz="0 0 0.15" rpy="0 0 0"/>
    <axis xyz="0 0 1"/>
  </joint>

  <joint name="base_to_imu" type="fixed">
    <parent link="base_link"/>
    <child link="imu_link"/>
    <origin xyz="0 0 0.1" rpy="0 0 0"/>
  </joint>


  <gazebo>
    <plugin filename="libgazebo_ros2_control.so" name="gazebo_ros2_control">
      <parameters>$(find Waypoint-Guided-Autonomous-Robot---ROS)/config/controllers.yaml</parameters>
      <ros>
        <remapping>/diff_cont/cmd_vel_unstamped:=/cmd_vel</remapping>
      </ros>
    </plugin>
  </gazebo>

  <ros2_control name="GazeboSystem" type="system">
    <hardware>
      <plugin>gazebo_ros2_control/GazeboSystem</plugin>
    </hardware>
    <joint name="base_to_left_wheel">
      <command_interface name="velocity"/>
      <state_interface name="position"/>
      <state_interface name="velocity"/>
    </joint>
    <joint name="base_to_right_wheel">
      <command_interface name="velocity"/>
      <state_interface name="position"/>
      <state_interface name="velocity"/>
    </joint>
  </ros2_control>

  <gazebo reference="caster_wheel">
    <mu1>0.0</mu1>
    <mu2>0.0</mu2>
  </gazebo>

  <gazebo reference="caster_wheel_back">
    <mu1>0.0</mu1>
    <mu2>0.0</mu2>
  </gazebo>

  <!-- GAZEBO LIDAR PLUGIN -->
  <gazebo reference="lidar">
    <sensor name="lidar_sensor" type="ray">
      <always_on>true</always_on>
      <visualize>true</visualize>
      <update_rate>10</update_rate>
      <ray>
        <scan>
          <horizontal>
            <samples>360</samples>
            <resolution>1</resolution>
            <min_angle>0</min_angle>
            <max_angle>6.283185307179586</max_angle>
          </horizontal>
        </scan>
        <range>
          <min>0.08</min>
          <max>30.0</max>
          <resolution>0.01</resolution>
        </range>
        <noise>
          <type>gaussian</type>
          <mean>0.0</mean>
          <stddev>0.01</stddev>
        </noise>
      </ray>
      <plugin name="lidar_plugin" filename="libgazebo_ros_ray_sensor.so">
        <ros>
          <remapping>~/out:=scan</remapping>
        </ros>
        <output_type>sensor_msgs/LaserScan</output_type>
        <frame_name>lidar</frame_name>
      </plugin>
    </sensor>
  </gazebo>

  <!-- GAZEBO IMU PLUGIN -->
  <gazebo reference="imu_link">
    <sensor name="imu_sensor" type="imu">
      <always_on>true</always_on>
      <update_rate>100</update_rate>
      <visualize>false</visualize>
      <imu>
        <angular_velocity>
          <x>
            <noise type="gaussian">
              <mean>0.0</mean>
              <stddev>0.009</stddev>
            </noise>
          </x>
          <y>
            <noise type="gaussian">
              <mean>0.0</mean>
              <stddev>0.009</stddev>
            </noise>
          </y>
          <z>
            <noise type="gaussian">
              <mean>0.0</mean>
              <stddev>0.008</stddev>
            </noise>
          </z>
        </angular_velocity>
        <linear_acceleration>
          <x>
            <noise type="gaussian">
              <mean>0.0</mean>
              <stddev>0.021</stddev>
            </noise>
          </x>
          <y>
            <noise type="gaussian">
              <mean>0.0</mean>
              <stddev>0.021</stddev>
            </noise>
          </y>
          <z>
            <noise type="gaussian">
              <mean>0.0</mean>
              <stddev>0.021</stddev>
            </noise>
          </z>
        </linear_acceleration>
      </imu>
      <plugin name="imu_plugin" filename="libgazebo_ros_imu_sensor.so">
        <initial_orientation_as_reference>false</initial_orientation_as_reference>
        <frame_name>imu_link</frame_name>
        <ros>
          <remapping>~/out:=imu</remapping>
        </ros>
      </plugin>
    </sensor>
  </gazebo>

</robot>